2021-08-12 20:59:57,488 - zyc - ERROR - 用户名密码验证失败！(535, b'Error: authentication failed')
Traceback (most recent call last):
  File "D:\work\PyCharm Community Edition 2020.3\web_auto_test\Common\email.py", line 74, in send
    smtp_server.login(self.sender, self.password)  # 登录
  File "D:\work\python3.9.0\lib\smtplib.py", line 734, in login
    raise last_exception
  File "D:\work\python3.9.0\lib\smtplib.py", line 723, in login
    (code, resp) = self.auth(
  File "D:\work\python3.9.0\lib\smtplib.py", line 646, in auth
    raise SMTPAuthenticationError(code, resp)
smtplib.SMTPAuthenticationError: (535, b'Error: authentication failed')
2021-08-12 20:59:57,535 - zyc - INFO - 发送邮件"test"成功! 收件人：643069710@qq.com。如果没有收到邮件，请检查垃圾箱，同时检查收件人地址是否正确
2021-08-12 21:01:31,314 - zyc - ERROR - 用户名密码验证失败！(535, b'Error: authentication failed')
Traceback (most recent call last):
  File "D:\work\PyCharm Community Edition 2020.3\web_auto_test\Common\email.py", line 74, in send
    smtp_server.login(self.sender, self.password)  # 登录
  File "D:\work\python3.9.0\lib\smtplib.py", line 734, in login
    raise last_exception
  File "D:\work\python3.9.0\lib\smtplib.py", line 723, in login
    (code, resp) = self.auth(
  File "D:\work\python3.9.0\lib\smtplib.py", line 646, in auth
    raise SMTPAuthenticationError(code, resp)
smtplib.SMTPAuthenticationError: (535, b'Error: authentication failed')
2021-08-12 21:01:31,330 - zyc - INFO - 发送邮件"test"成功! 收件人：643069710@qq.com。如果没有收到邮件，请检查垃圾箱，同时检查收件人地址是否正确
2021-08-12 21:09:41,075 - zyc - ERROR - 用户名密码验证失败！(535, b'Error: authentication failed')
Traceback (most recent call last):
  File "D:\work\PyCharm Community Edition 2020.3\web_auto_test\Common\email.py", line 74, in send
    smtp_server.login(self.sender, self.password)  # 登录
  File "D:\work\python3.9.0\lib\smtplib.py", line 734, in login
    raise last_exception
  File "D:\work\python3.9.0\lib\smtplib.py", line 723, in login
    (code, resp) = self.auth(
  File "D:\work\python3.9.0\lib\smtplib.py", line 646, in auth
    raise SMTPAuthenticationError(code, resp)
smtplib.SMTPAuthenticationError: (535, b'Error: authentication failed')
2021-08-12 21:09:41,080 - zyc - INFO - 发送邮件"test"成功! 收件人：643069710@qq.com。如果没有收到邮件，请检查垃圾箱，同时检查收件人地址是否正确
2021-08-12 21:10:15,578 - zyc - INFO - 发送邮件"test"成功! 收件人：643069710@qq.com。如果没有收到邮件，请检查垃圾箱，同时检查收件人地址是否正确
2021-08-12 21:15:45,607 - zyc - ERROR - 用户名密码验证失败！(535, b'Error: authentication failed')
Traceback (most recent call last):
  File "D:\work\PyCharm Community Edition 2020.3\web_auto_test\Common\email.py", line 74, in send
    smtp_server.login(self.sender, self.password)  # 登录
  File "D:\work\python3.9.0\lib\smtplib.py", line 734, in login
    raise last_exception
  File "D:\work\python3.9.0\lib\smtplib.py", line 723, in login
    (code, resp) = self.auth(
  File "D:\work\python3.9.0\lib\smtplib.py", line 646, in auth
    raise SMTPAuthenticationError(code, resp)
smtplib.SMTPAuthenticationError: (535, b'Error: authentication failed')
2021-08-12 21:15:45,622 - zyc - INFO - 发送邮件"test"成功! 收件人：643069710@qq.com。如果没有收到邮件，请检查垃圾箱，同时检查收件人地址是否正确
2021-08-12 21:15:47,763 - zyc - INFO - 发送邮件"test"成功! 收件人：643069710@qq.com。如果没有收到邮件，请检查垃圾箱，同时检查收件人地址是否正确
2021-08-12 21:16:19,907 - zyc - ERROR - 用户名密码验证失败！(535, b'Error: authentication failed')
Traceback (most recent call last):
  File "D:\work\PyCharm Community Edition 2020.3\web_auto_test\Common\email.py", line 74, in send
    smtp_server.login(self.sender, self.password)  # 登录
  File "D:\work\python3.9.0\lib\smtplib.py", line 734, in login
    raise last_exception
  File "D:\work\python3.9.0\lib\smtplib.py", line 723, in login
    (code, resp) = self.auth(
  File "D:\work\python3.9.0\lib\smtplib.py", line 646, in auth
    raise SMTPAuthenticationError(code, resp)
smtplib.SMTPAuthenticationError: (535, b'Error: authentication failed')
2021-08-12 21:16:19,923 - zyc - INFO - 发送邮件"test"成功! 收件人：643069710@qq.com。如果没有收到邮件，请检查垃圾箱，同时检查收件人地址是否正确
2021-08-12 21:16:54,211 - zyc - INFO - 发送邮件"test"成功! 收件人：643069710@qq.com。如果没有收到邮件，请检查垃圾箱，同时检查收件人地址是否正确
2021-08-12 21:18:36,956 - zyc - INFO - 发送邮件"test"成功! 收件人：643069710@qq.com。如果没有收到邮件，请检查垃圾箱，同时检查收件人地址是否正确
2021-08-12 21:26:21,908 - zyc - ERROR - 发送邮件失败,无法连接到SMTP服务器，检查网络以及SMTP服务器. <traceback object at 0x000001B03054BC40>
Traceback (most recent call last):
  File "D:\work\PyCharm Community Edition 2020.3\web_auto_test\Common\email.py", line 69, in send
    smtp_server = smtplib.SMTP(self.server,25)  # 连接sever
  File "D:\work\python3.9.0\lib\smtplib.py", line 253, in __init__
    (code, msg) = self.connect(host, port)
  File "D:\work\python3.9.0\lib\smtplib.py", line 339, in connect
    self.sock = self._get_socket(host, port, self.timeout)
  File "D:\work\python3.9.0\lib\smtplib.py", line 310, in _get_socket
    return socket.create_connection((host, port), timeout,
  File "D:\work\python3.9.0\lib\socket.py", line 822, in create_connection
    for res in getaddrinfo(host, port, 0, SOCK_STREAM):
  File "D:\work\python3.9.0\lib\socket.py", line 953, in getaddrinfo
    for res in _socket.getaddrinfo(host, port, family, type, proto, flags):
socket.gaierror: [Errno 11003] getaddrinfo failed
2021-08-12 21:26:56,977 - zyc - ERROR - 发送邮件失败,无法连接到SMTP服务器，检查网络以及SMTP服务器. <traceback object at 0x000001FE890BCCC0>
Traceback (most recent call last):
  File "D:\work\PyCharm Community Edition 2020.3\web_auto_test\Common\email.py", line 69, in send
    smtp_server = smtplib.SMTP(self.server)  # 连接sever
  File "D:\work\python3.9.0\lib\smtplib.py", line 253, in __init__
    (code, msg) = self.connect(host, port)
  File "D:\work\python3.9.0\lib\smtplib.py", line 339, in connect
    self.sock = self._get_socket(host, port, self.timeout)
  File "D:\work\python3.9.0\lib\smtplib.py", line 310, in _get_socket
    return socket.create_connection((host, port), timeout,
  File "D:\work\python3.9.0\lib\socket.py", line 822, in create_connection
    for res in getaddrinfo(host, port, 0, SOCK_STREAM):
  File "D:\work\python3.9.0\lib\socket.py", line 953, in getaddrinfo
    for res in _socket.getaddrinfo(host, port, family, type, proto, flags):
socket.gaierror: [Errno 11003] getaddrinfo failed
2021-08-12 21:27:40,777 - zyc - ERROR - 用户名密码验证失败！(535, b'Error: authentication failed')
Traceback (most recent call last):
  File "D:\work\PyCharm Community Edition 2020.3\web_auto_test\Common\email.py", line 74, in send
    smtp_server.login(self.sender, self.password)  # 登录
  File "D:\work\python3.9.0\lib\smtplib.py", line 734, in login
    raise last_exception
  File "D:\work\python3.9.0\lib\smtplib.py", line 723, in login
    (code, resp) = self.auth(
  File "D:\work\python3.9.0\lib\smtplib.py", line 646, in auth
    raise SMTPAuthenticationError(code, resp)
smtplib.SMTPAuthenticationError: (535, b'Error: authentication failed')
2021-08-12 21:28:55,536 - zyc - INFO - 发送邮件"test"成功! 收件人：zyc_tiger@163.com。如果没有收到邮件，请检查垃圾箱，同时检查收件人地址是否正确
2021-08-12 21:32:15,842 - zyc - INFO - 发送邮件"test"成功! 收件人：zyc_tiger@163.com。如果没有收到邮件，请检查垃圾箱，同时检查收件人地址是否正确
2021-08-12 21:34:36,338 - zyc - INFO - 发送邮件"test"成功! 收件人：zyc_tiger@163.com。如果没有收到邮件，请检查垃圾箱，同时检查收件人地址是否正确
2021-08-12 21:42:04,750 - zyc - INFO - 发送邮件"test"成功! 收件人：zyc_tiger@163.com。如果没有收到邮件，请检查垃圾箱，同时检查收件人地址是否正确
